bc@WKGK1QFG3:/mnt/c/Users/BRC8990/OneDrive - Humana/Desktop/python-main/python-main$ sudo python3 showiprouteafter.py
Enter your username: admin
Enter your password: Eve1234!
Loading Excel data (before): 100%|██████████████████████████████████████████████████████████████████████████████████████████████████████| 1/1 [00:00<00:00, 191.70it/s]
Saving to Excel: 0it [00:00, ?it/s]
Traceback (most recent call last):
  File "showiprouteafter.py", line 79, in <module>
    if df_after:
  File "/usr/local/lib/python3.8/dist-packages/pandas/core/generic.py", line 1466, in __nonzero__
    raise ValueError(
ValueError: The truth value of a DataFrame is ambiguous. Use a.empty, a.bool(), a.item(), a.any() or a.all().
Error in sys.excepthook:
Traceback (most recent call last):
  File "/usr/lib/python3/dist-packages/apport_python_hook.py", line 72, in apport_excepthook
    from apport.fileutils import likely_packaged, get_recent_crashes
  File "/usr/lib/python3/dist-packages/apport/__init__.py", line 5, in <module>
    from apport.report import Report
  File "/usr/lib/python3/dist-packages/apport/report.py", line 32, in <module>
    import apport.fileutils
  File "/usr/lib/python3/dist-packages/apport/fileutils.py", line 12, in <module>
    import os, glob, subprocess, os.path, time, pwd, sys, requests_unixsocket
  File "/usr/lib/python3/dist-packages/requests_unixsocket/__init__.py", line 1, in <module>
    import requests
  File "/usr/lib/python3/dist-packages/requests/__init__.py", line 95, in <module>
    from urllib3.contrib import pyopenssl
  File "/usr/lib/python3/dist-packages/urllib3/contrib/pyopenssl.py", line 46, in <module>
    import OpenSSL.SSL
  File "/usr/lib/python3/dist-packages/OpenSSL/__init__.py", line 8, in <module>
    from OpenSSL import crypto, SSL
  File "/usr/lib/python3/dist-packages/OpenSSL/crypto.py", line 1553, in <module>
    class X509StoreFlags(object):
  File "/usr/lib/python3/dist-packages/OpenSSL/crypto.py", line 1573, in X509StoreFlags
    CB_ISSUER_CHECK = _lib.X509_V_FLAG_CB_ISSUER_CHECK
AttributeError: module 'lib' has no attribute 'X509_V_FLAG_CB_ISSUER_CHECK'

Original exception was:
Traceback (most recent call last):
  File "showiprouteafter.py", line 79, in <module>
    if df_after:
  File "/usr/local/lib/python3.8/dist-packages/pandas/core/generic.py", line 1466, in __nonzero__
    raise ValueError(
ValueError: The truth value of a DataFrame is ambiguous. Use a.empty, a.bool(), a.item(), a.any() or a.all().
